<?xml version="1.0" encoding="utf-8"?>
<!-- =================================================================================== -->
<!-- |    This document was autogenerated by xacro from rising_std.urdf.xacro          | -->
<!-- |    EDITING THIS FILE BY HAND IS NOT RECOMMENDED                                 | -->
<!-- =================================================================================== -->
<robot name="rising">
  <!-- ***************** -->
  <!-- Imported elements -->
  <!-- ***************** -->
  <!-- First we import all posible elements defined in the urdf.xacro files. All these elements are defined as macro:xacros -->
  <!-- Source: https://en.wikipedia.org/wiki/List_of_moments_of_inertia-->
  <!-- Source: https://en.wikipedia.org/wiki/List_of_moments_of_inertia-->
  <!-- Source: https://en.wikipedia.org/wiki/List_of_moments_of_inertia-->
  <!-- in kg-->
  <!-- in kg-->
  <!-- in kg-->
  <!-- in kg-->
  <!-- Source: https://en.wikipedia.org/wiki/List_of_moments_of_inertia-->
  <!-- Source: https://en.wikipedia.org/wiki/List_of_moments_of_inertia-->
  <!-- in kg-->
  <!-- in kg-->
  <!-- in kg-->
  <!-- in kg-->
  <!-- source en.wikipedia.org/wiki/List_of_moments_of_inertia-->
  <!-- This file unifies all sensors that can be used on simulation, defined as xacro:macros -->
  <!-- Includes -->
  <!-- Include KINOVA GEN3 ARM -->
  <!--xacro:include filename="$(find kortex_description)/arms/gen3/6dof/urdf/gen3_macro.xacro" />
	<xacro:include filename="$(find kortex_description)/arms/gen3/6dof/urdf/gen3_transmission_macro.xacro" /-->
  <!-- Include KINOVA GEN3 GRIPPER -->
  <!--xacro:include filename="$(find kortex_description)/grippers/gen3_lite_2f/urdf/gen3_lite_2f_macro.xacro" />
	<xacro:include filename="$(find kortex_description)/grippers/gen3_lite_2f/urdf/gen3_lite_2f_transmission_macro.xacro" /-->
  <gazebo>
    <plugin filename="libgazebo_ros_control.so" name="ros_control">
      <!--robotNamespace>/rising</robotNamespace-->
      <robotParam>robot_description</robotParam>
      <controlPeriod>0.001</controlPeriod>
      <robotSimType>gazebo_ros_control/DefaultRobotHWSim</robotSimType>
    </plugin>
  </gazebo>
  <!--xacro:if value="$(arg ros_planar_move_plugin)">

		<xacro:if value="$(arg omni_wheels)">
			<xacro:omni_steering prefix="$(arg prefix)" publish_tf="true"/>
		</xacro:if>

		<xacro:unless value="$(arg omni_wheels)">
			<xacro:skid_steering prefix="$(arg prefix)" publish_tf="true"/>
		</xacro:unless>

	</xacro:if> -->
  <!-- ************** -->
  <!-- GAZEBO PLUGINS -->
  <!-- ************** -->
  <!-- Gazebo ros control pluggins >
        <xacro:ros_control/-->
  <!--xacro:gazebo_colors prefix="$(arg prefix)"/-->
  <!-- *************** -->
  <!-- Robots Elements -->
  <!-- *************** -->
  <!-- Here we create the robot elements using the xacro:macros imported at the beggining of this file -->
  <!--<xacro:property name="flippers_width" value="0.1"/> -->
  <link name="rising_base_footprint">
    <visual>
      <origin rpy="0 0 0" xyz="0 0 0"/>
      <geometry>
        <box size="0.001 0.001 0.001"/>
      </geometry>
    </visual>
  </link>
  <joint name="rising_base_footprint_joint" type="fixed">
    <!-- DUDA: Valores -->
    <origin rpy="0 0 0" xyz="0 0 0"/>
    <parent link="rising_base_footprint"/>
    <child link="rising_base_link"/>
  </joint>
  <!-- BASE_LINK -->
  <link name="rising_base_link">
    <inertial>
      <mass value="50"/>
      <origin xyz="0 0 0.11"/>
      <inertia ixx="1.38375" ixy="0" ixz="0" iyy="2.98481666667" iyz="0" izz="3.28856666667"/>
    </inertial>
    <visual>
      <origin rpy="0 0 0" xyz="0 0 0"/>
      <geometry>
        <mesh filename="package://rising_description/meshes/base/rising_base_final.dae"/>
      </geometry>
      <material name="dark_grey">
        <color rgba="0.4 0.4 0.4 1.0"/>
      </material>
    </visual>
    <collision>
      <origin rpy="0 0 0 " xyz="0 0 0"/>
      <geometry>
        <mesh filename="package://rising_description/meshes/base/rising_base_final.stl"/>
      </geometry>
    </collision>
  </link>
  <gazebo reference="rising_base_link">
    <material>Gazebo/Black</material>
  </gazebo>
  <joint name="rising_front_flipper_joint" type="continuous">
    <parent link="rising_base_link"/>
    <child link="rising_front_flipper_link"/>
    <origin rpy="0 -1.57 0" xyz="0.27455 -0.0 0.0"/>
    <axis rpy="0 0 0" xyz="0 1 0"/>
    <limit effort="100" velocity="100"/>
    <joint_properties damping="0.5" friction="0.5"/>
  </joint>
  <link name="rising_front_flipper_link">
    <visual>
      <origin rpy="0 0 0" xyz="0 0 0"/>
      <geometry>
        <mesh filename="package://rising_description/meshes/flippers/front_flippers.dae"/>
      </geometry>
    </visual>
    <collision>
      <origin rpy="0 0 0" xyz="0 0 0"/>
      <geometry>
        <mesh filename="package://rising_description/meshes/flippers/collision_front_flippers_final.dae" scale="0.001 0.001 0.001"/>
      </geometry>
      <!-- origin xyz="0 0 0" rpy="0 0 0"/>
                <geometry>
                   <mesh filename="package://rising_description/meshes/flippers/collision_front_flippers.dae" />
                    <!- - <cylinder length="${front_flipper_height}" radius="${front_flipper_radius}" />- ->
                </geometry-->
    </collision>
    <inertial>
      <mass value="8"/>
      <origin xyz="0.11 0 0"/>
      <inertia ixx="0.307277333333" ixy="0" ixz="0" iyy="0.148877333333" iyz="0" izz="0.404933333333"/>
    </inertial>
  </link>
  <joint name="rising_front_left_master_wheel_joint" type="continuous">
    <parent link="rising_front_flipper_link"/>
    <child link="rising_front_left_master_wheel_link"/>
    <origin rpy="0 0 0" xyz="0 0.274 0"/>
    <axis rpy="0 0 0" xyz="0 1 0"/>
    <limit effort="100" velocity="600"/>
    <joint_properties damping="0.0" friction="0.0"/>
  </joint>
  <link name="rising_front_left_master_wheel_link">
    <!--visual>
              <origin xyz="0 0 0" rpy="${M_PI/2} 0 0"/>
              <geometry>
                <cylinder length="${master_wheel_height}" radius="${master_wheel_radius}" />
              </geometry>
            </visual-->
    <collision>
      <origin rpy="1.57079632679 0 0" xyz="0 0 0"/>
      <geometry>
        <cylinder length="0.06" radius="0.1"/>
      </geometry>
    </collision>
    <inertial>
      <mass value="1"/>
      <origin rpy="1.57079632679 0 0" xyz="0 0 0"/>
      <inertia ixx="0.0028" ixy="0" ixz="0" iyy="0.0028" iyz="0" izz="0.005"/>
    </inertial>
  </link>
  <joint name="rising_front_left_slave_wheel_joint" type="continuous">
    <parent link="rising_front_flipper_link"/>
    <child link="rising_front_left_slave_wheel_link"/>
    <origin rpy="0 0 0" xyz="0.25387 0.274 -0.04"/>
    <axis rpy="0 0 0" xyz="0 1 0"/>
    <limit effort="100" velocity="600"/>
    <mimic joint="{prefix}master_wheel_joint" multiplier="1.0" offset="0"/>
    <joint_properties damping="0.0" friction="0.0"/>
  </joint>
  <link name="rising_front_left_slave_wheel_link">
    <!--visual>
              <origin xyz="0 0 0" rpy="${M_PI/2} 0 0"/>
              <geometry>
                <cylinder length="${slave_wheel_height}" radius="${slave_wheel_radius}" />
              </geometry>
            </visual-->
    <collision>
      <origin rpy="1.57079632679 0 0" xyz="0 0 0"/>
      <geometry>
        <cylinder length="0.06" radius="0.06"/>
      </geometry>
    </collision>
    <inertial>
      <mass value="0.5"/>
      <origin rpy="1.57079632679 0 0" xyz="0 0 0"/>
      <inertia ixx="0.0006" ixy="0" ixz="0" iyy="0.0006" iyz="0" izz="0.0009"/>
    </inertial>
  </link>
  <joint name="rising_front_left_small_wheel_1_joint" type="continuous">
    <parent link="rising_front_flipper_link"/>
    <child link="rising_front_left_small_wheel_1_link"/>
    <origin rpy="0 0 0" xyz="0.14135 0.274 0.049"/>
    <axis rpy="0 0 0" xyz="0 1 0"/>
    <limit effort="100" velocity="600"/>
    <mimic joint="{prefix}master_wheel_joint" multiplier="1.0" offset="0"/>
    <joint_properties damping="0.0" friction="0.0"/>
  </joint>
  <link name="rising_front_left_small_wheel_1_link">
    <!--visual>
              <origin xyz="0 0 0" rpy="${M_PI/2} 0 0"/>
              <geometry>
                <cylinder length="${small_wheel_height}" radius="${small_wheel_radius}" />
              </geometry>
            </visual-->
    <collision>
      <origin rpy="1.57079632679 0 0" xyz="0 0 0"/>
      <geometry>
        <cylinder length="0.06" radius="0.01"/>
      </geometry>
    </collision>
    <inertial>
      <mass value="0.1"/>
      <origin rpy="1.57079632679 0 0" xyz="0 0 0"/>
      <inertia ixx="3.25e-05" ixy="0" ixz="0" iyy="3.25e-05" iyz="0" izz="5e-06"/>
    </inertial>
  </link>
  <joint name="rising_front_left_small_wheel_2_joint" type="continuous">
    <parent link="rising_front_flipper_link"/>
    <child link="rising_front_left_small_wheel_2_link"/>
    <origin rpy="0 0 0" xyz="0.09 0.274 0.0639"/>
    <axis rpy="0 0 0" xyz="0 1 0"/>
    <limit effort="100" velocity="600"/>
    <mimic joint="{prefix}master_wheel_joint" multiplier="1.0" offset="0"/>
    <joint_properties damping="0.0" friction="0.0"/>
  </joint>
  <link name="rising_front_left_small_wheel_2_link">
    <!--visual>
              <origin xyz="0 0 0" rpy="${M_PI/2} 0 0"/>
              <geometry>
                <cylinder length="${small_wheel_height}" radius="${small_wheel_radius}" />
              </geometry>
            </visual-->
    <collision>
      <origin rpy="1.57079632679 0 0" xyz="0 0 0"/>
      <geometry>
        <cylinder length="0.06" radius="0.01"/>
      </geometry>
    </collision>
    <inertial>
      <mass value="0.1"/>
      <origin rpy="1.57079632679 0 0" xyz="0 0 0"/>
      <inertia ixx="3.25e-05" ixy="0" ixz="0" iyy="3.25e-05" iyz="0" izz="5e-06"/>
    </inertial>
  </link>
  <joint name="rising_front_left_small_wheel_3_joint" type="continuous">
    <parent link="rising_front_flipper_link"/>
    <child link="rising_front_left_small_wheel_3_link"/>
    <origin rpy="0 0 0" xyz="0.19 0.274 0.0315"/>
    <axis rpy="0 0 0" xyz="0 1 0"/>
    <limit effort="100" velocity="600"/>
    <mimic joint="{prefix}master_wheel_joint" multiplier="1.0" offset="0"/>
    <joint_properties damping="0.0" friction="0.0"/>
  </joint>
  <link name="rising_front_left_small_wheel_3_link">
    <!--visual>
              <origin xyz="0 0 0" rpy="${M_PI/2} 0 0"/>
              <geometry>
                <cylinder length="${small_wheel_height}" radius="${small_wheel_radius}" />
              </geometry>
            </visual-->
    <collision>
      <origin rpy="1.57079632679 0 0" xyz="0 0 0"/>
      <geometry>
        <cylinder length="0.06" radius="0.01"/>
      </geometry>
    </collision>
    <inertial>
      <mass value="0.1"/>
      <origin rpy="1.57079632679 0 0" xyz="0 0 0"/>
      <inertia ixx="3.25e-05" ixy="0" ixz="0" iyy="3.25e-05" iyz="0" izz="5e-06"/>
    </inertial>
  </link>
  <!-- Transmission is important to link the joints and the controller (see rising_control/config/rising_control.yaml)-->
  <transmission name="rising_front_left_master_wheel_joint_trans" params="prefix">
    <type>transmission_interface/SimpleTransmission</type>
    <joint name="rising_front_left_master_wheel_joint">
      <hardwareInterface>hardware_interface/VelocityJointInterface</hardwareInterface>
    </joint>
    <actuator name="rising_front_left_master_wheel_joint_motor">
      <mechanicalReduction>1</mechanicalReduction>
      <motorTorqueConstant>20</motorTorqueConstant>
    </actuator>
  </transmission>
  <gazebo reference="rising_front_left__wheel_link">
    <mu1 value="10000"/>
    <mu2 value="10000"/>
    <kp value="10000000.0"/>
    <kd value="1.0"/>
    <fdir1 value="1 0 0"/>
    <material>Gazebo/Yellow</material>
    <turnGravityOff>false</turnGravityOff>
  </gazebo>
  <gazebo>
    <plugin filename="libroboticsgroup_gazebo_mimic_joint_plugin.so" name="rising_front_left_mimic_joint_plugin">
      <joint>rising_front_left_master_wheel_joint</joint>
      <mimicJoint>rising_front_left_slave_wheel_joint</mimicJoint>
      <multiplier>1.0</multiplier>
      <offset>0</offset>
      <sensitiveness>0.0</sensitiveness>
      <!-- if absolute difference between setpoint and process value is below this threshold, do nothing; 0.0 = disable [rad] -->
      <maxEffort>1.0</maxEffort>
    </plugin>
  </gazebo>
  <joint name="rising_front_right_master_wheel_joint" type="continuous">
    <parent link="rising_front_flipper_link"/>
    <child link="rising_front_right_master_wheel_link"/>
    <origin rpy="0 0 0" xyz="0 -0.274 0"/>
    <axis rpy="0 0 0" xyz="0 1 0"/>
    <limit effort="100" velocity="600"/>
    <joint_properties damping="0.0" friction="0.0"/>
  </joint>
  <link name="rising_front_right_master_wheel_link">
    <!--visual>
              <origin xyz="0 0 0" rpy="${M_PI/2} 0 0"/>
              <geometry>
                <cylinder length="${master_wheel_height}" radius="${master_wheel_radius}" />
              </geometry>
            </visual-->
    <collision>
      <origin rpy="1.57079632679 0 0" xyz="0 0 0"/>
      <geometry>
        <cylinder length="0.06" radius="0.1"/>
      </geometry>
    </collision>
    <inertial>
      <mass value="1"/>
      <origin rpy="1.57079632679 0 0" xyz="0 0 0"/>
      <inertia ixx="0.0028" ixy="0" ixz="0" iyy="0.0028" iyz="0" izz="0.005"/>
    </inertial>
  </link>
  <joint name="rising_front_right_slave_wheel_joint" type="continuous">
    <parent link="rising_front_flipper_link"/>
    <child link="rising_front_right_slave_wheel_link"/>
    <origin rpy="0 0 0" xyz="0.25387 -0.274 -0.04"/>
    <axis rpy="0 0 0" xyz="0 1 0"/>
    <limit effort="100" velocity="600"/>
    <mimic joint="{prefix}master_wheel_joint" multiplier="1.0" offset="0"/>
    <joint_properties damping="0.0" friction="0.0"/>
  </joint>
  <link name="rising_front_right_slave_wheel_link">
    <!--visual>
              <origin xyz="0 0 0" rpy="${M_PI/2} 0 0"/>
              <geometry>
                <cylinder length="${slave_wheel_height}" radius="${slave_wheel_radius}" />
              </geometry>
            </visual-->
    <collision>
      <origin rpy="1.57079632679 0 0" xyz="0 0 0"/>
      <geometry>
        <cylinder length="0.06" radius="0.06"/>
      </geometry>
    </collision>
    <inertial>
      <mass value="0.5"/>
      <origin rpy="1.57079632679 0 0" xyz="0 0 0"/>
      <inertia ixx="0.0006" ixy="0" ixz="0" iyy="0.0006" iyz="0" izz="0.0009"/>
    </inertial>
  </link>
  <joint name="rising_front_right_small_wheel_1_joint" type="continuous">
    <parent link="rising_front_flipper_link"/>
    <child link="rising_front_right_small_wheel_1_link"/>
    <origin rpy="0 0 0" xyz="0.14135 -0.274 0.049"/>
    <axis rpy="0 0 0" xyz="0 1 0"/>
    <limit effort="100" velocity="600"/>
    <mimic joint="{prefix}master_wheel_joint" multiplier="1.0" offset="0"/>
    <joint_properties damping="0.0" friction="0.0"/>
  </joint>
  <link name="rising_front_right_small_wheel_1_link">
    <!--visual>
              <origin xyz="0 0 0" rpy="${M_PI/2} 0 0"/>
              <geometry>
                <cylinder length="${small_wheel_height}" radius="${small_wheel_radius}" />
              </geometry>
            </visual-->
    <collision>
      <origin rpy="1.57079632679 0 0" xyz="0 0 0"/>
      <geometry>
        <cylinder length="0.06" radius="0.01"/>
      </geometry>
    </collision>
    <inertial>
      <mass value="0.1"/>
      <origin rpy="1.57079632679 0 0" xyz="0 0 0"/>
      <inertia ixx="3.25e-05" ixy="0" ixz="0" iyy="3.25e-05" iyz="0" izz="5e-06"/>
    </inertial>
  </link>
  <joint name="rising_front_right_small_wheel_2_joint" type="continuous">
    <parent link="rising_front_flipper_link"/>
    <child link="rising_front_right_small_wheel_2_link"/>
    <origin rpy="0 0 0" xyz="0.09 -0.274 0.0639"/>
    <axis rpy="0 0 0" xyz="0 1 0"/>
    <limit effort="100" velocity="600"/>
    <mimic joint="{prefix}master_wheel_joint" multiplier="1.0" offset="0"/>
    <joint_properties damping="0.0" friction="0.0"/>
  </joint>
  <link name="rising_front_right_small_wheel_2_link">
    <!--visual>
              <origin xyz="0 0 0" rpy="${M_PI/2} 0 0"/>
              <geometry>
                <cylinder length="${small_wheel_height}" radius="${small_wheel_radius}" />
              </geometry>
            </visual-->
    <collision>
      <origin rpy="1.57079632679 0 0" xyz="0 0 0"/>
      <geometry>
        <cylinder length="0.06" radius="0.01"/>
      </geometry>
    </collision>
    <inertial>
      <mass value="0.1"/>
      <origin rpy="1.57079632679 0 0" xyz="0 0 0"/>
      <inertia ixx="3.25e-05" ixy="0" ixz="0" iyy="3.25e-05" iyz="0" izz="5e-06"/>
    </inertial>
  </link>
  <joint name="rising_front_right_small_wheel_3_joint" type="continuous">
    <parent link="rising_front_flipper_link"/>
    <child link="rising_front_right_small_wheel_3_link"/>
    <origin rpy="0 0 0" xyz="0.19 -0.274 0.0315"/>
    <axis rpy="0 0 0" xyz="0 1 0"/>
    <limit effort="100" velocity="600"/>
    <mimic joint="{prefix}master_wheel_joint" multiplier="1.0" offset="0"/>
    <joint_properties damping="0.0" friction="0.0"/>
  </joint>
  <link name="rising_front_right_small_wheel_3_link">
    <!--visual>
              <origin xyz="0 0 0" rpy="${M_PI/2} 0 0"/>
              <geometry>
                <cylinder length="${small_wheel_height}" radius="${small_wheel_radius}" />
              </geometry>
            </visual-->
    <collision>
      <origin rpy="1.57079632679 0 0" xyz="0 0 0"/>
      <geometry>
        <cylinder length="0.06" radius="0.01"/>
      </geometry>
    </collision>
    <inertial>
      <mass value="0.1"/>
      <origin rpy="1.57079632679 0 0" xyz="0 0 0"/>
      <inertia ixx="3.25e-05" ixy="0" ixz="0" iyy="3.25e-05" iyz="0" izz="5e-06"/>
    </inertial>
  </link>
  <!-- Transmission is important to link the joints and the controller (see rising_control/config/rising_control.yaml)-->
  <transmission name="rising_front_right_master_wheel_joint_trans" params="prefix">
    <type>transmission_interface/SimpleTransmission</type>
    <joint name="rising_front_right_master_wheel_joint">
      <hardwareInterface>hardware_interface/VelocityJointInterface</hardwareInterface>
    </joint>
    <actuator name="rising_front_right_master_wheel_joint_motor">
      <mechanicalReduction>1</mechanicalReduction>
      <motorTorqueConstant>20</motorTorqueConstant>
    </actuator>
  </transmission>
  <gazebo reference="rising_front_right__wheel_link">
    <mu1 value="10000"/>
    <mu2 value="10000"/>
    <kp value="10000000.0"/>
    <kd value="1.0"/>
    <fdir1 value="1 0 0"/>
    <material>Gazebo/Yellow</material>
    <turnGravityOff>false</turnGravityOff>
  </gazebo>
  <gazebo>
    <plugin filename="libroboticsgroup_gazebo_mimic_joint_plugin.so" name="rising_front_right_mimic_joint_plugin">
      <joint>rising_front_right_master_wheel_joint</joint>
      <mimicJoint>rising_front_right_slave_wheel_joint</mimicJoint>
      <multiplier>1.0</multiplier>
      <offset>0</offset>
      <sensitiveness>0.0</sensitiveness>
      <!-- if absolute difference between setpoint and process value is below this threshold, do nothing; 0.0 = disable [rad] -->
      <maxEffort>1.0</maxEffort>
    </plugin>
  </gazebo>
  <!-- Transmission is important to link the joints and the controller -->
  <transmission name="rising_front_flipper_joint_trans">
    <type>transmission_interface/SimpleTransmission</type>
    <joint name="rising_front_flipper_joint">
      <hardwareInterface>hardware_interface/PositionJointInterface</hardwareInterface>
    </joint>
    <actuator name="rising_front_flipper_motor_joint">
      <hardwareInterface>hardware_interface/PositionActuatorInterface</hardwareInterface>
      <mechanicalReduction>1</mechanicalReduction>
      <!--motorTorqueConstant>20</motorTorqueConstant-->
    </actuator>
  </transmission>
  <gazebo reference="rising_front_flipper_link">
    <mu1 value="1.0"/>
    <mu2 value="1.0"/>
    <kp value="10000000.0"/>
    <kd value="1.0"/>
    <fdir1 value="1 0 0"/>
    <material>Gazebo/Grey</material>
    <turnGravityOff>false</turnGravityOff>
  </gazebo>
  <joint name="rising_back_flipper_joint" type="continuous">
    <parent link="rising_base_link"/>
    <child link="rising_back_flipper_link"/>
    <origin rpy="0 1.57 0" xyz="-0.27455 -0.0 0.0"/>
    <axis rpy="0 0 0" xyz="0 1 0"/>
    <limit effort="100" velocity="100"/>
    <joint_properties damping="0.5" friction="0.5"/>
  </joint>
  <link name="rising_back_flipper_link">
    <visual>
      <origin rpy="0 0 0" xyz="0 0 0"/>
      <geometry>
        <mesh filename="package://rising_description/meshes/flippers/back_flippers.dae"/>
      </geometry>
    </visual>
    <collision>
      <origin rpy="1.57079632679 0 0" xyz="-0.13688 0 0"/>
      <geometry>
        <mesh filename="package://rising_description/meshes/flippers/collision_back_flippers_final.dae" scale="0.001 0.001 0.001"/>
      </geometry>
      <!--origin xyz="0 0 0" rpy="0 0 0"/>
               <geometry>
                   <mesh filename="package://rising_description/meshes/flippers/collision_back_flippers.dae" />
                   <!- - <cylinder length="${back_flipper_height}" radius="${back_flipper_radius}" /> - ->
               </geometry-->
    </collision>
    <inertial>
      <mass value="8"/>
      <origin xyz="-0.11 0 0"/>
      <inertia ixx="0.307277333333" ixy="0" ixz="0" iyy="0.148877333333" iyz="0" izz="0.404933333333"/>
    </inertial>
  </link>
  <joint name="rising_back_left_master_wheel_joint" type="continuous">
    <parent link="rising_back_flipper_link"/>
    <child link="rising_back_left_master_wheel_link"/>
    <origin rpy="0 0 0" xyz="0 0.274 0"/>
    <axis rpy="0 0 0" xyz="0 1 0"/>
    <limit effort="100" velocity="600"/>
    <joint_properties damping="0.0" friction="0.0"/>
  </joint>
  <link name="rising_back_left_master_wheel_link">
    <!--visual>
              <origin xyz="0 0 0" rpy="${M_PI/2} 0 0"/>
              <geometry>
                <cylinder length="${master_wheel_height}" radius="${master_wheel_radius}" />
              </geometry>
            </visual-->
    <collision>
      <origin rpy="1.57079632679 0 0" xyz="0 0 0"/>
      <geometry>
        <cylinder length="0.06" radius="0.1"/>
      </geometry>
    </collision>
    <inertial>
      <mass value="1"/>
      <origin rpy="1.57079632679 0 0" xyz="0 0 0"/>
      <inertia ixx="0.0028" ixy="0" ixz="0" iyy="0.0028" iyz="0" izz="0.005"/>
    </inertial>
  </link>
  <joint name="rising_back_left_slave_wheel_joint" type="continuous">
    <parent link="rising_back_flipper_link"/>
    <child link="rising_back_left_slave_wheel_link"/>
    <origin rpy="0 0 0" xyz="-0.25387 0.274 -0.04"/>
    <axis rpy="0 0 0" xyz="0 1 0"/>
    <limit effort="100" velocity="600"/>
    <mimic joint="{prefix}master_wheel_joint" multiplier="1.0" offset="0"/>
    <joint_properties damping="0.0" friction="0.0"/>
  </joint>
  <link name="rising_back_left_slave_wheel_link">
    <!--visual>
              <origin xyz="0 0 0" rpy="${M_PI/2} 0 0"/>
              <geometry>
                <cylinder length="${slave_wheel_height}" radius="${slave_wheel_radius}" />
              </geometry>
            </visual-->
    <collision>
      <origin rpy="1.57079632679 0 0" xyz="0 0 0"/>
      <geometry>
        <cylinder length="0.06" radius="0.06"/>
      </geometry>
    </collision>
    <inertial>
      <mass value="0.5"/>
      <origin rpy="1.57079632679 0 0" xyz="0 0 0"/>
      <inertia ixx="0.0006" ixy="0" ixz="0" iyy="0.0006" iyz="0" izz="0.0009"/>
    </inertial>
  </link>
  <joint name="rising_back_left_small_wheel_1_joint" type="continuous">
    <parent link="rising_back_flipper_link"/>
    <child link="rising_back_left_small_wheel_1_link"/>
    <origin rpy="0 0 0" xyz="-0.14135 0.274 0.049"/>
    <axis rpy="0 0 0" xyz="0 1 0"/>
    <limit effort="100" velocity="600"/>
    <mimic joint="{prefix}master_wheel_joint" multiplier="1.0" offset="0"/>
    <joint_properties damping="0.0" friction="0.0"/>
  </joint>
  <link name="rising_back_left_small_wheel_1_link">
    <!--visual>
              <origin xyz="0 0 0" rpy="${M_PI/2} 0 0"/>
              <geometry>
                <cylinder length="${small_wheel_height}" radius="${small_wheel_radius}" />
              </geometry>
            </visual-->
    <collision>
      <origin rpy="1.57079632679 0 0" xyz="0 0 0"/>
      <geometry>
        <cylinder length="0.06" radius="0.01"/>
      </geometry>
    </collision>
    <inertial>
      <mass value="0.1"/>
      <origin rpy="1.57079632679 0 0" xyz="0 0 0"/>
      <inertia ixx="3.25e-05" ixy="0" ixz="0" iyy="3.25e-05" iyz="0" izz="5e-06"/>
    </inertial>
  </link>
  <joint name="rising_back_left_small_wheel_2_joint" type="continuous">
    <parent link="rising_back_flipper_link"/>
    <child link="rising_back_left_small_wheel_2_link"/>
    <origin rpy="0 0 0" xyz="-0.09 0.274 0.0639"/>
    <axis rpy="0 0 0" xyz="0 1 0"/>
    <limit effort="100" velocity="600"/>
    <mimic joint="{prefix}master_wheel_joint" multiplier="1.0" offset="0"/>
    <joint_properties damping="0.0" friction="0.0"/>
  </joint>
  <link name="rising_back_left_small_wheel_2_link">
    <!--visual>
              <origin xyz="0 0 0" rpy="${M_PI/2} 0 0"/>
              <geometry>
                <cylinder length="${small_wheel_height}" radius="${small_wheel_radius}" />
              </geometry>
            </visual-->
    <collision>
      <origin rpy="1.57079632679 0 0" xyz="0 0 0"/>
      <geometry>
        <cylinder length="0.06" radius="0.01"/>
      </geometry>
    </collision>
    <inertial>
      <mass value="0.1"/>
      <origin rpy="1.57079632679 0 0" xyz="0 0 0"/>
      <inertia ixx="3.25e-05" ixy="0" ixz="0" iyy="3.25e-05" iyz="0" izz="5e-06"/>
    </inertial>
  </link>
  <joint name="rising_back_left_small_wheel_3_joint" type="continuous">
    <parent link="rising_back_flipper_link"/>
    <child link="rising_back_left_small_wheel_3_link"/>
    <origin rpy="0 0 0" xyz="-0.19 0.274 0.0315"/>
    <axis rpy="0 0 0" xyz="0 1 0"/>
    <limit effort="100" velocity="600"/>
    <mimic joint="{prefix}master_wheel_joint" multiplier="1.0" offset="0"/>
    <joint_properties damping="0.0" friction="0.0"/>
  </joint>
  <link name="rising_back_left_small_wheel_3_link">
    <!--visual>
              <origin xyz="0 0 0" rpy="${M_PI/2} 0 0"/>
              <geometry>
                <cylinder length="${small_wheel_height}" radius="${small_wheel_radius}" />
              </geometry>
            </visual-->
    <collision>
      <origin rpy="1.57079632679 0 0" xyz="0 0 0"/>
      <geometry>
        <cylinder length="0.06" radius="0.01"/>
      </geometry>
    </collision>
    <inertial>
      <mass value="0.1"/>
      <origin rpy="1.57079632679 0 0" xyz="0 0 0"/>
      <inertia ixx="3.25e-05" ixy="0" ixz="0" iyy="3.25e-05" iyz="0" izz="5e-06"/>
    </inertial>
  </link>
  <!-- Transmission is important to link the joints and the controller (see rising_control/config/rising_control.yaml)-->
  <transmission name="rising_back_left_master_wheel_joint_trans" params="prefix">
    <type>transmission_interface/SimpleTransmission</type>
    <joint name="rising_back_left_master_wheel_joint">
      <hardwareInterface>hardware_interface/VelocityJointInterface</hardwareInterface>
    </joint>
    <actuator name="rising_back_left_master_wheel_joint_motor">
      <mechanicalReduction>1</mechanicalReduction>
      <motorTorqueConstant>20</motorTorqueConstant>
    </actuator>
  </transmission>
  <gazebo reference="rising_back_left__wheel_link">
    <mu1 value="10000"/>
    <mu2 value="10000"/>
    <kp value="10000000.0"/>
    <kd value="1.0"/>
    <fdir1 value="1 0 0"/>
    <material>Gazebo/Yellow</material>
    <turnGravityOff>false</turnGravityOff>
  </gazebo>
  <gazebo>
    <plugin filename="libroboticsgroup_gazebo_mimic_joint_plugin.so" name="rising_back_left_mimic_joint_plugin">
      <joint>rising_back_left_master_wheel_joint</joint>
      <mimicJoint>rising_back_left_slave_wheel_joint</mimicJoint>
      <multiplier>1.0</multiplier>
      <offset>0</offset>
      <sensitiveness>0.0</sensitiveness>
      <!-- if absolute difference between setpoint and process value is below this threshold, do nothing; 0.0 = disable [rad] -->
      <maxEffort>1.0</maxEffort>
    </plugin>
  </gazebo>
  <joint name="rising_back_right_master_wheel_joint" type="continuous">
    <parent link="rising_back_flipper_link"/>
    <child link="rising_back_right_master_wheel_link"/>
    <origin rpy="0 0 0" xyz="0 -0.274 0"/>
    <axis rpy="0 0 0" xyz="0 1 0"/>
    <limit effort="100" velocity="600"/>
    <joint_properties damping="0.0" friction="0.0"/>
  </joint>
  <link name="rising_back_right_master_wheel_link">
    <!--visual>
              <origin xyz="0 0 0" rpy="${M_PI/2} 0 0"/>
              <geometry>
                <cylinder length="${master_wheel_height}" radius="${master_wheel_radius}" />
              </geometry>
            </visual-->
    <collision>
      <origin rpy="1.57079632679 0 0" xyz="0 0 0"/>
      <geometry>
        <cylinder length="0.06" radius="0.1"/>
      </geometry>
    </collision>
    <inertial>
      <mass value="1"/>
      <origin rpy="1.57079632679 0 0" xyz="0 0 0"/>
      <inertia ixx="0.0028" ixy="0" ixz="0" iyy="0.0028" iyz="0" izz="0.005"/>
    </inertial>
  </link>
  <joint name="rising_back_right_slave_wheel_joint" type="continuous">
    <parent link="rising_back_flipper_link"/>
    <child link="rising_back_right_slave_wheel_link"/>
    <origin rpy="0 0 0" xyz="-0.25387 -0.274 -0.04"/>
    <axis rpy="0 0 0" xyz="0 1 0"/>
    <limit effort="100" velocity="600"/>
    <mimic joint="{prefix}master_wheel_joint" multiplier="1.0" offset="0"/>
    <joint_properties damping="0.0" friction="0.0"/>
  </joint>
  <link name="rising_back_right_slave_wheel_link">
    <!--visual>
              <origin xyz="0 0 0" rpy="${M_PI/2} 0 0"/>
              <geometry>
                <cylinder length="${slave_wheel_height}" radius="${slave_wheel_radius}" />
              </geometry>
            </visual-->
    <collision>
      <origin rpy="1.57079632679 0 0" xyz="0 0 0"/>
      <geometry>
        <cylinder length="0.06" radius="0.06"/>
      </geometry>
    </collision>
    <inertial>
      <mass value="0.5"/>
      <origin rpy="1.57079632679 0 0" xyz="0 0 0"/>
      <inertia ixx="0.0006" ixy="0" ixz="0" iyy="0.0006" iyz="0" izz="0.0009"/>
    </inertial>
  </link>
  <joint name="rising_back_right_small_wheel_1_joint" type="continuous">
    <parent link="rising_back_flipper_link"/>
    <child link="rising_back_right_small_wheel_1_link"/>
    <origin rpy="0 0 0" xyz="-0.14135 -0.274 0.049"/>
    <axis rpy="0 0 0" xyz="0 1 0"/>
    <limit effort="100" velocity="600"/>
    <mimic joint="{prefix}master_wheel_joint" multiplier="1.0" offset="0"/>
    <joint_properties damping="0.0" friction="0.0"/>
  </joint>
  <link name="rising_back_right_small_wheel_1_link">
    <!--visual>
              <origin xyz="0 0 0" rpy="${M_PI/2} 0 0"/>
              <geometry>
                <cylinder length="${small_wheel_height}" radius="${small_wheel_radius}" />
              </geometry>
            </visual-->
    <collision>
      <origin rpy="1.57079632679 0 0" xyz="0 0 0"/>
      <geometry>
        <cylinder length="0.06" radius="0.01"/>
      </geometry>
    </collision>
    <inertial>
      <mass value="0.1"/>
      <origin rpy="1.57079632679 0 0" xyz="0 0 0"/>
      <inertia ixx="3.25e-05" ixy="0" ixz="0" iyy="3.25e-05" iyz="0" izz="5e-06"/>
    </inertial>
  </link>
  <joint name="rising_back_right_small_wheel_2_joint" type="continuous">
    <parent link="rising_back_flipper_link"/>
    <child link="rising_back_right_small_wheel_2_link"/>
    <origin rpy="0 0 0" xyz="-0.09 -0.274 0.0639"/>
    <axis rpy="0 0 0" xyz="0 1 0"/>
    <limit effort="100" velocity="600"/>
    <mimic joint="{prefix}master_wheel_joint" multiplier="1.0" offset="0"/>
    <joint_properties damping="0.0" friction="0.0"/>
  </joint>
  <link name="rising_back_right_small_wheel_2_link">
    <!--visual>
              <origin xyz="0 0 0" rpy="${M_PI/2} 0 0"/>
              <geometry>
                <cylinder length="${small_wheel_height}" radius="${small_wheel_radius}" />
              </geometry>
            </visual-->
    <collision>
      <origin rpy="1.57079632679 0 0" xyz="0 0 0"/>
      <geometry>
        <cylinder length="0.06" radius="0.01"/>
      </geometry>
    </collision>
    <inertial>
      <mass value="0.1"/>
      <origin rpy="1.57079632679 0 0" xyz="0 0 0"/>
      <inertia ixx="3.25e-05" ixy="0" ixz="0" iyy="3.25e-05" iyz="0" izz="5e-06"/>
    </inertial>
  </link>
  <joint name="rising_back_right_small_wheel_3_joint" type="continuous">
    <parent link="rising_back_flipper_link"/>
    <child link="rising_back_right_small_wheel_3_link"/>
    <origin rpy="0 0 0" xyz="-0.19 -0.274 0.0315"/>
    <axis rpy="0 0 0" xyz="0 1 0"/>
    <limit effort="100" velocity="600"/>
    <mimic joint="{prefix}master_wheel_joint" multiplier="1.0" offset="0"/>
    <joint_properties damping="0.0" friction="0.0"/>
  </joint>
  <link name="rising_back_right_small_wheel_3_link">
    <!--visual>
              <origin xyz="0 0 0" rpy="${M_PI/2} 0 0"/>
              <geometry>
                <cylinder length="${small_wheel_height}" radius="${small_wheel_radius}" />
              </geometry>
            </visual-->
    <collision>
      <origin rpy="1.57079632679 0 0" xyz="0 0 0"/>
      <geometry>
        <cylinder length="0.06" radius="0.01"/>
      </geometry>
    </collision>
    <inertial>
      <mass value="0.1"/>
      <origin rpy="1.57079632679 0 0" xyz="0 0 0"/>
      <inertia ixx="3.25e-05" ixy="0" ixz="0" iyy="3.25e-05" iyz="0" izz="5e-06"/>
    </inertial>
  </link>
  <!-- Transmission is important to link the joints and the controller (see rising_control/config/rising_control.yaml)-->
  <transmission name="rising_back_right_master_wheel_joint_trans" params="prefix">
    <type>transmission_interface/SimpleTransmission</type>
    <joint name="rising_back_right_master_wheel_joint">
      <hardwareInterface>hardware_interface/VelocityJointInterface</hardwareInterface>
    </joint>
    <actuator name="rising_back_right_master_wheel_joint_motor">
      <mechanicalReduction>1</mechanicalReduction>
      <motorTorqueConstant>20</motorTorqueConstant>
    </actuator>
  </transmission>
  <gazebo reference="rising_back_right__wheel_link">
    <mu1 value="10000"/>
    <mu2 value="10000"/>
    <kp value="10000000.0"/>
    <kd value="1.0"/>
    <fdir1 value="1 0 0"/>
    <material>Gazebo/Yellow</material>
    <turnGravityOff>false</turnGravityOff>
  </gazebo>
  <gazebo>
    <plugin filename="libroboticsgroup_gazebo_mimic_joint_plugin.so" name="rising_back_right_mimic_joint_plugin">
      <joint>rising_back_right_master_wheel_joint</joint>
      <mimicJoint>rising_back_right_slave_wheel_joint</mimicJoint>
      <multiplier>1.0</multiplier>
      <offset>0</offset>
      <sensitiveness>0.0</sensitiveness>
      <!-- if absolute difference between setpoint and process value is below this threshold, do nothing; 0.0 = disable [rad] -->
      <maxEffort>1.0</maxEffort>
    </plugin>
  </gazebo>
  <!-- Transmission is important to link the joints and the controller -->
  <transmission name="rising_back_flipper_joint_trans">
    <type>transmission_interface/SimpleTransmission</type>
    <joint name="rising_back_flipper_joint">
      <hardwareInterface>hardware_interface/PositionJointInterface</hardwareInterface>
    </joint>
    <actuator name="rising_back_flipper_motor_joint">
      <hardwareInterface>hardware_interface/PositionActuatorInterface</hardwareInterface>
      <mechanicalReduction>1</mechanicalReduction>
      <!--motorTorqueConstant>20</motorTorqueConstant-->
    </actuator>
  </transmission>
  <gazebo reference="rising_back_flipper_link">
    <mu1 value="1.0"/>
    <mu2 value="1.00"/>
    <kp value="10000000.0"/>
    <kd value="1.0"/>
    <fdir1 value="1 0 0"/>
    <material>Gazebo/Grey</material>
    <turnGravityOff>false</turnGravityOff>
  </gazebo>
  <joint name="rising_front_3d_laser_base_joint" type="fixed">
    <origin rpy="0 0.785398163397 0" xyz="0.27894 0 0.20667"/>
    <parent link="rising_base_link"/>
    <child link="rising_front_3d_laser_base_link"/>
  </joint>
  <link name="rising_front_3d_laser_base_link">
    <visual>
      <!-- origin xyz="0 0 0" rpy="0 0 1.5708"/ -->
      <origin rpy="0 0 0" xyz="0 0 0"/>
      <geometry>
        <mesh filename="package://robotnik_sensors/meshes/rs_bpearl.stl"/>
      </geometry>
      <material name="blackgray_color">
        <color rgba="0.25 0.25 0.25 1"/>
      </material>
    </visual>
    <collision>
      <origin rpy="0 0 0" xyz="0 0 0"/>
      <geometry>
        <mesh filename="package://robotnik_sensors/meshes/rs_bpearl.stl"/>
      </geometry>
    </collision>
    <inertial>
      <!-- The following are not reliable values, and should not be used for modeling -->
      <mass value="0.92"/>
      <origin xyz="0 0 0.055"/>
      <inertia ixx="0.00187227666667" ixy="0" ixz="0" iyy="0.00187227666667" iyz="0" izz="0.00188922"/>
    </inertial>
  </link>
  <joint name="rising_front_3d_laser_joint" type="fixed">
    <parent link="rising_front_3d_laser_base_link"/>
    <child link="rising_front_3d_laser_link"/>
    <origin rpy="0 0 0" xyz="0 0 0.09427"/>
  </joint>
  <link name="rising_front_3d_laser_link"/>
  <gazebo reference="rising_front_3d_laser_base_link">
    <visual>
      <material>
        <ambient>0.5 0.5 0.5 1.0</ambient>
        <diffuse>0.250754 0.250754 0.250754 1.0</diffuse>
        <specular>0.2508273 0.2508273 0.2508273 1.0</specular>
        <emissive>0.0 0.0 0.0 0.0</emissive>
      </material>
    </visual>
  </gazebo>
  <gazebo reference="rising_front_3d_laser_link">
    <visual>
      <material>
        <ambient>1.2 0.2 0.2 1.0</ambient>
        <diffuse>0.250754 0.250754 0.250754 1.0</diffuse>
        <specular>0.2508273 0.2508273 0.2508273 1.0</specular>
        <emissive>0.0 0.0 0.0 0.0</emissive>
      </material>
    </visual>
    <sensor name="rising_front_3d_laser_sensor" type="ray">
      <pose>0 0 0 0 0 0.0</pose>
      <visualize>false</visualize>
      <update_rate>15</update_rate>
      <ray>
        <scan>
          <horizontal>
            <!-- for a high quality simulation -->
            <samples>1200</samples>
            <min_angle>-3.14159265359</min_angle>
            <max_angle>3.14159265359</max_angle>
          </horizontal>
          <vertical>
            <samples>32</samples>
            <min_angle>-0.0872664625997</min_angle>
            <!-- bpearl has 90 degrees of vertical field of view-->
            <max_angle> 1.4835298642</max_angle>
          </vertical>
        </scan>
        <range>
          <min>0.1</min>
          <max>90</max>
          <resolution>0.01</resolution>
        </range>
        <noise>
          <type>none</type>
        </noise>
      </ray>
      <plugin filename="libgazebo_ros_velodyne_laser.so" name="rising_front_3d_laser_controller">
        <topicName>front_3d_laser/points</topicName>
        <frameName>/rising_front_3d_laser_link</frameName>
        <gaussianNoise>0.008</gaussianNoise>
      </plugin>
    </sensor>
  </gazebo>
  <joint name="rising_front_rgbd_camera_base_joint" type="fixed">
    <origin rpy="0 0 0" xyz="0.408 0 0.00225"/>
    <parent link="rising_base_link"/>
    <child link="rising_front_rgbd_camera_base_link"/>
  </joint>
  <link name="rising_front_rgbd_camera_base_link"/>
  <!-- camera body, with origin at bottom screw mount -->
  <joint name="rising_front_rgbd_camera_joint" type="fixed">
    <parent link="rising_front_rgbd_camera_base_link"/>
    <child link="rising_front_rgbd_camera_link"/>
    <origin rpy="0 0 0" xyz="0.01 0.02 0"/>
    <child link="rising_front_rgbd_camera_link"/>
  </joint>
  <link name="rising_front_rgbd_camera_link">
    <!-- camera link is aligned with the infrared sensor 1 that is "in the middle of the camera", not the one in the edge -->
    <visual>
      <origin rpy="1.57079632679 0 1.57079632679" xyz="0.0149 -0.0175 0"/>
      <geometry>
        <!-- <box size="${d435_cam_width} ${d435_cam_height} ${d435_cam_depth}"/> -->
        <mesh filename="package://robotnik_sensors/meshes/intel_d435.dae"/>
      </geometry>
    </visual>
    <collision>
      <origin rpy="0 0 0" xyz="0 -0.0175 0"/>
      <geometry>
        <box size="0.02505 0.09 0.025"/>
      </geometry>
    </collision>
    <inertial>
      <origin rpy="0 0 0" xyz="0.0025 -0.015 0.0"/>
      <mass value="0.1"/>
      <inertia ixx="7.27083333333e-05" ixy="0" ixz="0" iyy="1.04166666667e-05" iyz="0" izz="7.27083333333e-05"/>
    </inertial>
  </link>
  <!-- camera depth joints and links -->
  <joint name="rising_front_rgbd_camera_depth_joint" type="fixed">
    <origin rpy="0 0 0" xyz="0 0 0"/>
    <parent link="rising_front_rgbd_camera_link"/>
    <child link="rising_front_rgbd_camera_depth_frame"/>
  </joint>
  <link name="rising_front_rgbd_camera_depth_frame"/>
  <joint name="rising_front_rgbd_camera_depth_optical_joint" type="fixed">
    <origin rpy="-1.57079632679 0 -1.57079632679" xyz="0 0 0"/>
    <parent link="rising_front_rgbd_camera_depth_frame"/>
    <child link="rising_front_rgbd_camera_depth_optical_frame"/>
  </joint>
  <link name="rising_front_rgbd_camera_depth_optical_frame"/>
  <!-- camera left IR joints and links -->
  <joint name="rising_front_rgbd_camera_infra1_joint" type="fixed">
    <origin rpy="0 0 0" xyz="0 0.0 0"/>
    <parent link="rising_front_rgbd_camera_link"/>
    <child link="rising_front_rgbd_camera_infra1_frame"/>
  </joint>
  <link name="rising_front_rgbd_camera_infra1_frame"/>
  <joint name="rising_front_rgbd_camera_infra1_optical_joint" type="fixed">
    <origin rpy="-1.57079632679 0 -1.57079632679" xyz="0 0 0"/>
    <parent link="rising_front_rgbd_camera_infra1_frame"/>
    <child link="rising_front_rgbd_camera_infra1_optical_frame"/>
  </joint>
  <link name="rising_front_rgbd_camera_infra1_optical_frame"/>
  <!-- camera right IR joints and links -->
  <joint name="rising_front_rgbd_camera_infra2_joint" type="fixed">
    <origin rpy="0 0 0" xyz="0 -0.05 0"/>
    <parent link="rising_front_rgbd_camera_link"/>
    <child link="rising_front_rgbd_camera_infra2_frame"/>
  </joint>
  <link name="rising_front_rgbd_camera_infra2_frame"/>
  <joint name="rising_front_rgbd_camera_infra2_optical_joint" type="fixed">
    <origin rpy="-1.57079632679 0 -1.57079632679" xyz="0 0 0"/>
    <parent link="rising_front_rgbd_camera_infra2_frame"/>
    <child link="rising_front_rgbd_camera_infra2_optical_frame"/>
  </joint>
  <link name="rising_front_rgbd_camera_infra2_optical_frame"/>
  <!-- camera color joints and links -->
  <joint name="rising_front_rgbd_camera_color_joint" type="fixed">
    <origin rpy="0 0 0" xyz="0 0.015 0"/>
    <parent link="rising_front_rgbd_camera_link"/>
    <child link="rising_front_rgbd_camera_color_frame"/>
  </joint>
  <link name="rising_front_rgbd_camera_color_frame"/>
  <joint name="rising_front_rgbd_camera_color_optical_joint" type="fixed">
    <origin rpy="-1.57079632679 0 -1.57079632679" xyz="0 0 0"/>
    <parent link="rising_front_rgbd_camera_color_frame"/>
    <child link="rising_front_rgbd_camera_color_optical_frame"/>
  </joint>
  <link name="rising_front_rgbd_camera_color_optical_frame"/>
  <gazebo reference="rising_front_rgbd_camera_link">
    <self_collide>0</self_collide>
    <enable_wind>0</enable_wind>
    <kinematic>0</kinematic>
    <gravity>1</gravity>
    <!--<mu>1</mu>-->
    <mu2>1</mu2>
    <fdir1>0 0 0</fdir1>
    <!--<slip1>0</slip1>
     <slip2>0</slip2>-->
    <kp>1e+13</kp>
    <kd>1</kd>
    <!--<max_vel>0.01</max_vel>
     <min_depth>0</min_depth>-->
    <sensor name="rising_front_rgbd_cameracolor" type="camera">
      <camera name="rising_front_rgbd_camera">
        <horizontal_fov>1.21125850088</horizontal_fov>
        <image>
          <width>1920</width>
          <height>1080</height>
          <format>RGB_INT8</format>
        </image>
        <clip>
          <near>0.1</near>
          <far>100</far>
        </clip>
        <noise>
          <type>gaussian</type>
          <mean>0.0</mean>
          <stddev>0.007</stddev>
        </noise>
      </camera>
      <always_on>1</always_on>
      <update_rate>30</update_rate>
      <visualize>1</visualize>
    </sensor>
    <sensor name="rising_front_rgbd_cameraired1" type="camera">
      <camera name="rising_front_rgbd_camera">
        <horizontal_fov>1.4870205227</horizontal_fov>
        <image>
          <width>1280</width>
          <height>720</height>
          <format>L_INT8</format>
        </image>
        <clip>
          <near>0.1</near>
          <far>100</far>
        </clip>
        <noise>
          <type>gaussian</type>
          <mean>0.0</mean>
          <stddev>0.05</stddev>
        </noise>
      </camera>
      <always_on>1</always_on>
      <update_rate>90</update_rate>
      <visualize>0</visualize>
    </sensor>
    <sensor name="rising_front_rgbd_cameraired2" type="camera">
      <camera name="rising_front_rgbd_camera">
        <horizontal_fov>1.4870205227</horizontal_fov>
        <image>
          <width>1280</width>
          <height>720</height>
          <format>L_INT8</format>
        </image>
        <clip>
          <near>0.1</near>
          <far>100</far>
        </clip>
        <noise>
          <type>gaussian</type>
          <mean>0.0</mean>
          <stddev>0.05</stddev>
        </noise>
      </camera>
      <always_on>1</always_on>
      <update_rate>90</update_rate>
      <visualize>0</visualize>
    </sensor>
    <sensor name="rising_front_rgbd_cameradepth" type="depth">
      <camera name="rising_front_rgbd_camera">
        <horizontal_fov>1.4870205227</horizontal_fov>
        <image>
          <width>1280</width>
          <height>720</height>
        </image>
        <clip>
          <near>0.1</near>
          <far>100</far>
        </clip>
        <noise>
          <type>gaussian</type>
          <mean>0.0</mean>
          <stddev>0.100</stddev>
        </noise>
      </camera>
      <always_on>1</always_on>
      <update_rate>90</update_rate>
      <visualize>0</visualize>
    </sensor>
  </gazebo>
  <gazebo>
    <plugin filename="librealsense_gazebo_plugin.so" name="front_rgbd_camera">
      <prefix>rising_front_rgbd_camera</prefix>
      <depthUpdateRate>60.0</depthUpdateRate>
      <colorUpdateRate>60.0</colorUpdateRate>
      <infraredUpdateRate>60.0</infraredUpdateRate>
      <depthTopicName>depth/image_raw</depthTopicName>
      <depthCameraInfoTopicName>depth/camera_info</depthCameraInfoTopicName>
      <colorTopicName>color/image_raw</colorTopicName>
      <colorCameraInfoTopicName>color/camera_info</colorCameraInfoTopicName>
      <infrared1TopicName>infra1/image_raw</infrared1TopicName>
      <infrared1CameraInfoTopicName>infra1/camera_info</infrared1CameraInfoTopicName>
      <infrared2TopicName>infra2/image_raw</infrared2TopicName>
      <infrared2CameraInfoTopicName>infra2/camera_info</infrared2CameraInfoTopicName>
      <colorOpticalframeName>rising_front_rgbd_camera_color_optical_frame</colorOpticalframeName>
      <depthOpticalframeName>rising_front_rgbd_camera_depth_optical_frame</depthOpticalframeName>
      <infrared1OpticalframeName>rising_front_rgbd_camera_left_ir_optical_frame</infrared1OpticalframeName>
      <infrared2OpticalframeName>rising_front_rgbd_camera_right_ir_optical_frame</infrared2OpticalframeName>
      <rangeMinDepth>0.2</rangeMinDepth>
      <rangeMaxDepth>10.0</rangeMaxDepth>
      <pointCloud>false</pointCloud>
      <pointCloudTopicName>depth/points</pointCloudTopicName>
      <pointCloudCutoff>0.5</pointCloudCutoff>
    </plugin>
  </gazebo>
  <joint name="rising_back_rgbd_camera_base_joint" type="fixed">
    <origin rpy="0 0 3.14" xyz="-0.408 0 0.0023"/>
    <parent link="rising_base_link"/>
    <child link="rising_back_rgbd_camera_base_link"/>
  </joint>
  <link name="rising_back_rgbd_camera_base_link"/>
  <!-- camera body, with origin at bottom screw mount -->
  <joint name="rising_back_rgbd_camera_joint" type="fixed">
    <parent link="rising_back_rgbd_camera_base_link"/>
    <child link="rising_back_rgbd_camera_link"/>
    <origin rpy="0 0 0" xyz="0.01 0.02 0"/>
    <child link="rising_back_rgbd_camera_link"/>
  </joint>
  <link name="rising_back_rgbd_camera_link">
    <!-- camera link is aligned with the infrared sensor 1 that is "in the middle of the camera", not the one in the edge -->
    <visual>
      <origin rpy="1.57079632679 0 1.57079632679" xyz="0.0149 -0.0175 0"/>
      <geometry>
        <!-- <box size="${d435_cam_width} ${d435_cam_height} ${d435_cam_depth}"/> -->
        <mesh filename="package://robotnik_sensors/meshes/intel_d435.dae"/>
      </geometry>
    </visual>
    <collision>
      <origin rpy="0 0 0" xyz="0 -0.0175 0"/>
      <geometry>
        <box size="0.02505 0.09 0.025"/>
      </geometry>
    </collision>
    <inertial>
      <origin rpy="0 0 0" xyz="0.0025 -0.015 0.0"/>
      <mass value="0.1"/>
      <inertia ixx="7.27083333333e-05" ixy="0" ixz="0" iyy="1.04166666667e-05" iyz="0" izz="7.27083333333e-05"/>
    </inertial>
  </link>
  <!-- camera depth joints and links -->
  <joint name="rising_back_rgbd_camera_depth_joint" type="fixed">
    <origin rpy="0 0 0" xyz="0 0 0"/>
    <parent link="rising_back_rgbd_camera_link"/>
    <child link="rising_back_rgbd_camera_depth_frame"/>
  </joint>
  <link name="rising_back_rgbd_camera_depth_frame"/>
  <joint name="rising_back_rgbd_camera_depth_optical_joint" type="fixed">
    <origin rpy="-1.57079632679 0 -1.57079632679" xyz="0 0 0"/>
    <parent link="rising_back_rgbd_camera_depth_frame"/>
    <child link="rising_back_rgbd_camera_depth_optical_frame"/>
  </joint>
  <link name="rising_back_rgbd_camera_depth_optical_frame"/>
  <!-- camera left IR joints and links -->
  <joint name="rising_back_rgbd_camera_infra1_joint" type="fixed">
    <origin rpy="0 0 0" xyz="0 0.0 0"/>
    <parent link="rising_back_rgbd_camera_link"/>
    <child link="rising_back_rgbd_camera_infra1_frame"/>
  </joint>
  <link name="rising_back_rgbd_camera_infra1_frame"/>
  <joint name="rising_back_rgbd_camera_infra1_optical_joint" type="fixed">
    <origin rpy="-1.57079632679 0 -1.57079632679" xyz="0 0 0"/>
    <parent link="rising_back_rgbd_camera_infra1_frame"/>
    <child link="rising_back_rgbd_camera_infra1_optical_frame"/>
  </joint>
  <link name="rising_back_rgbd_camera_infra1_optical_frame"/>
  <!-- camera right IR joints and links -->
  <joint name="rising_back_rgbd_camera_infra2_joint" type="fixed">
    <origin rpy="0 0 0" xyz="0 -0.05 0"/>
    <parent link="rising_back_rgbd_camera_link"/>
    <child link="rising_back_rgbd_camera_infra2_frame"/>
  </joint>
  <link name="rising_back_rgbd_camera_infra2_frame"/>
  <joint name="rising_back_rgbd_camera_infra2_optical_joint" type="fixed">
    <origin rpy="-1.57079632679 0 -1.57079632679" xyz="0 0 0"/>
    <parent link="rising_back_rgbd_camera_infra2_frame"/>
    <child link="rising_back_rgbd_camera_infra2_optical_frame"/>
  </joint>
  <link name="rising_back_rgbd_camera_infra2_optical_frame"/>
  <!-- camera color joints and links -->
  <joint name="rising_back_rgbd_camera_color_joint" type="fixed">
    <origin rpy="0 0 0" xyz="0 0.015 0"/>
    <parent link="rising_back_rgbd_camera_link"/>
    <child link="rising_back_rgbd_camera_color_frame"/>
  </joint>
  <link name="rising_back_rgbd_camera_color_frame"/>
  <joint name="rising_back_rgbd_camera_color_optical_joint" type="fixed">
    <origin rpy="-1.57079632679 0 -1.57079632679" xyz="0 0 0"/>
    <parent link="rising_back_rgbd_camera_color_frame"/>
    <child link="rising_back_rgbd_camera_color_optical_frame"/>
  </joint>
  <link name="rising_back_rgbd_camera_color_optical_frame"/>
  <gazebo reference="rising_back_rgbd_camera_link">
    <self_collide>0</self_collide>
    <enable_wind>0</enable_wind>
    <kinematic>0</kinematic>
    <gravity>1</gravity>
    <!--<mu>1</mu>-->
    <mu2>1</mu2>
    <fdir1>0 0 0</fdir1>
    <!--<slip1>0</slip1>
     <slip2>0</slip2>-->
    <kp>1e+13</kp>
    <kd>1</kd>
    <!--<max_vel>0.01</max_vel>
     <min_depth>0</min_depth>-->
    <sensor name="rising_back_rgbd_cameracolor" type="camera">
      <camera name="rising_back_rgbd_camera">
        <horizontal_fov>1.21125850088</horizontal_fov>
        <image>
          <width>1920</width>
          <height>1080</height>
          <format>RGB_INT8</format>
        </image>
        <clip>
          <near>0.1</near>
          <far>100</far>
        </clip>
        <noise>
          <type>gaussian</type>
          <mean>0.0</mean>
          <stddev>0.007</stddev>
        </noise>
      </camera>
      <always_on>1</always_on>
      <update_rate>30</update_rate>
      <visualize>1</visualize>
    </sensor>
    <sensor name="rising_back_rgbd_cameraired1" type="camera">
      <camera name="rising_back_rgbd_camera">
        <horizontal_fov>1.4870205227</horizontal_fov>
        <image>
          <width>1280</width>
          <height>720</height>
          <format>L_INT8</format>
        </image>
        <clip>
          <near>0.1</near>
          <far>100</far>
        </clip>
        <noise>
          <type>gaussian</type>
          <mean>0.0</mean>
          <stddev>0.05</stddev>
        </noise>
      </camera>
      <always_on>1</always_on>
      <update_rate>90</update_rate>
      <visualize>0</visualize>
    </sensor>
    <sensor name="rising_back_rgbd_cameraired2" type="camera">
      <camera name="rising_back_rgbd_camera">
        <horizontal_fov>1.4870205227</horizontal_fov>
        <image>
          <width>1280</width>
          <height>720</height>
          <format>L_INT8</format>
        </image>
        <clip>
          <near>0.1</near>
          <far>100</far>
        </clip>
        <noise>
          <type>gaussian</type>
          <mean>0.0</mean>
          <stddev>0.05</stddev>
        </noise>
      </camera>
      <always_on>1</always_on>
      <update_rate>90</update_rate>
      <visualize>0</visualize>
    </sensor>
    <sensor name="rising_back_rgbd_cameradepth" type="depth">
      <camera name="rising_back_rgbd_camera">
        <horizontal_fov>1.4870205227</horizontal_fov>
        <image>
          <width>1280</width>
          <height>720</height>
        </image>
        <clip>
          <near>0.1</near>
          <far>100</far>
        </clip>
        <noise>
          <type>gaussian</type>
          <mean>0.0</mean>
          <stddev>0.100</stddev>
        </noise>
      </camera>
      <always_on>1</always_on>
      <update_rate>90</update_rate>
      <visualize>0</visualize>
    </sensor>
  </gazebo>
  <gazebo>
    <plugin filename="librealsense_gazebo_plugin.so" name="back_rgbd_camera">
      <prefix>rising_back_rgbd_camera</prefix>
      <depthUpdateRate>60.0</depthUpdateRate>
      <colorUpdateRate>60.0</colorUpdateRate>
      <infraredUpdateRate>60.0</infraredUpdateRate>
      <depthTopicName>depth/image_raw</depthTopicName>
      <depthCameraInfoTopicName>depth/camera_info</depthCameraInfoTopicName>
      <colorTopicName>color/image_raw</colorTopicName>
      <colorCameraInfoTopicName>color/camera_info</colorCameraInfoTopicName>
      <infrared1TopicName>infra1/image_raw</infrared1TopicName>
      <infrared1CameraInfoTopicName>infra1/camera_info</infrared1CameraInfoTopicName>
      <infrared2TopicName>infra2/image_raw</infrared2TopicName>
      <infrared2CameraInfoTopicName>infra2/camera_info</infrared2CameraInfoTopicName>
      <colorOpticalframeName>rising_back_rgbd_camera_color_optical_frame</colorOpticalframeName>
      <depthOpticalframeName>rising_back_rgbd_camera_depth_optical_frame</depthOpticalframeName>
      <infrared1OpticalframeName>rising_back_rgbd_camera_left_ir_optical_frame</infrared1OpticalframeName>
      <infrared2OpticalframeName>rising_back_rgbd_camera_right_ir_optical_frame</infrared2OpticalframeName>
      <rangeMinDepth>0.2</rangeMinDepth>
      <rangeMaxDepth>10.0</rangeMaxDepth>
      <pointCloud>false</pointCloud>
      <pointCloudTopicName>depth/points</pointCloudTopicName>
      <pointCloudCutoff>0.5</pointCloudCutoff>
    </plugin>
  </gazebo>
  <joint name="rising_imu_joint" type="fixed">
    <axis xyz="1 0 0"/>
    <!--origin xyz="0 0 0.2825"/-->
    <origin rpy="0 0 0" xyz="0.07136 0.0365 0.2711"/>
    <parent link="rising_base_link"/>
    <child link="rising_imu_link"/>
  </joint>
  <link name="rising_imu_link">
    <inertial>
      <origin rpy="0 0 0" xyz="0.0 0 0.01"/>
      <mass value="0.05"/>
      <inertia ixx="3.33333333333e-06" ixy="0" ixz="0" iyy="3.33333333333e-06" iyz="0" izz="3.33333333333e-06"/>
    </inertial>
    <visual>
      <origin rpy="0 0 0" xyz="0 0 0"/>
      <geometry>
        <box size="0.001 0.001 0.001"/>
      </geometry>
    </visual>
    <collision>
      <origin rpy="0 0 0" xyz="0 0 0"/>
      <geometry>
        <box size=".001 .001 .001"/>
      </geometry>
    </collision>
  </link>
  <gazebo>
    <plugin filename="libhector_gazebo_ros_imu.so" name="rising_imu_controller">
      <alwaysOn>true</alwaysOn>
      <topicName>imu/data</topicName>
      <serviceName>rising_imuimu/service</serviceName>
      <bodyName>rising_imu_link</bodyName>
      <frameId>rising_imu_link</frameId>
      <updateRate>50.0</updateRate>
      <gaussianNoise>0.00</gaussianNoise>
      <yawOffset>0.0</yawOffset>
      <yawDrift>0.0</yawDrift>
      <yawGaussianNoise>0.0</yawGaussianNoise>
      <!-- angular velocities parameters -->
      <rateOffset>0.0 0.0 0.0</rateOffset>
      <rateDrift>0.0 0.0 0.0</rateDrift>
      <rateGaussianNoise>0.0 0.0 0.0</rateGaussianNoise>
      <!-- linear accelerations parameters -->
      <accelOffset>0.0 0.0 0.0</accelOffset>
      <accelDrift>0.0 0.0 0.0</accelDrift>
      <accelGaussianNoise>0.0 0.0 0.0</accelGaussianNoise>
    </plugin>
  </gazebo>
</robot>
